<?xml version="1.0" encoding="utf-8"?>
<!-- This URDF was automatically created by SolidWorks to URDF Exporter! Originally created by Stephen Brawner (brawner@gmail.com) 
     Commit Version: 1.6.0-1-g15f4949  Build Version: 1.6.7594.29634
     For more information, please see http://wiki.ros.org/sw_urdf_exporter -->
<robot
  name="rk_bot">
    <link 
    name="dummy_link">
  </link>
  <joint
    name="dummy_joint"
    type="fixed">
    <parent
      link="dummy_link" />
    <child
      link="chassis" />
  </joint>
  <link
    name="chassis">
    <inertial>
      <origin
        xyz="0.00374066589152284 2.74235412283863E-17 8.10097689622267E-21"
        rpy="0 0 0" />
      <mass
        value="6.3775995785298" />
      <inertia
        ixx="0.0342295273576062"
        ixy="1.11363182362414E-17"
        ixz="5.74622716833175E-19"
        iyy="0.143807948564283"
        iyz="1.35957611294182E-19"
        izz="0.175326392077361" />
    </inertial>
    <visual>
      <origin
        xyz="0 0 0"
        rpy="0 0 0" />
      <geometry>
        <mesh
          filename="package://rk_bot/meshes/chassis.STL" />
      </geometry>
      <material
        name="">
        <color
          rgba="0.792156862745098 0.819607843137255 0.933333333333333 1" />
      </material>
    </visual>
    <collision>
      <origin
        xyz="0 0 0"
        rpy="0 0 0" />
      <geometry>
        <mesh
          filename="package://rk_bot/meshes/chassis.STL" />
      </geometry>
    </collision>
  </link>
  <link
    name="front_left_leg">
    <inertial>
      <origin
        xyz="7.42709367834438E-05 -6.74004497303038E-06 0.0331269063227782"
        rpy="0 0 0" />
      <mass
        value="0.114192911912365" />
      <inertia
        ixx="9.08102975741437E-05"
        ixy="-1.12808217855419E-06"
        ixz="1.52065802340836E-19"
        iyy="6.98637794411562E-05"
        iyz="-3.27434416233595E-20"
        izz="3.65285981598052E-05" />
    </inertial>
    <visual>
      <origin
        xyz="0 0 0"
        rpy="0 0 0" />
      <geometry>
        <mesh
          filename="package://rk_bot/meshes/front_left_leg.STL" />
      </geometry>
      <material
        name="">
        <color
          rgba="0.792156862745098 0.819607843137255 0.933333333333333 1" />
      </material>
    </visual>
    <collision>
      <origin
        xyz="0 0 0"
        rpy="0 0 0" />
      <geometry>
        <mesh
          filename="package://rk_bot/meshes/front_left_leg.STL" />
      </geometry>
    </collision>
  </link>
  <joint
    name="front_left_leg_joint"
    type="revolute">
    <origin
      xyz="0.225000147341898 0.100002743826739 -0.0674599999999996"
      rpy="0 0 0" />
    <parent
      link="chassis" />
    <child
      link="front_left_leg" />
    <axis
      xyz="0 0 1" />
    <limit effort='1' velocity='10' lower='-0.5' upper='0.5'/>
  </joint>
  <transmission name="front_left_transmission">
    <type>transmission_interface/SimpleTransmission</type>
    <joint name="front_left_leg_joint">
      <hardwareInterface>EffortJointInterface</hardwareInterface>
    </joint>
    <actuator name="front_left_motor">
      <mechanicalReduction>50</mechanicalReduction>
      <hardwareInterface>hardware_interface/EffortJointInterface</hardwareInterface>
    </actuator>
  </transmission>
  <link
    name="front_left_wheel">
    <inertial>
      <origin
        xyz="-2.77555756156289E-17 -2.77555756156289E-17 0"
        rpy="0 0 0" />
      <mass
        value="0.0376991118430775" />
      <inertia
        ixx="1.08533993270826E-05"
        ixy="2.77557426617064E-07"
        ixz="-1.09808226316414E-22"
        iyy="1.60072178611101E-05"
        iyz="-2.50428930450427E-22"
        izz="1.08384946548848E-05" />
    </inertial>
    <visual>
      <origin
        xyz="0 0 0"
        rpy="0 0 0" />
      <geometry>
        <mesh
          filename="package://rk_bot/meshes/front_left_wheel.STL" />
      </geometry>
      <material
        name="">
        <color
          rgba="0.792156862745098 0.819607843137255 0.933333333333333 1" />
      </material>
    </visual>
    <collision>
      <origin
        xyz="0 0 0"
        rpy="0 0 0" />
      <geometry>
        <mesh
          filename="package://rk_bot/meshes/front_left_wheel.STL" />
      </geometry>
    </collision>
  </link>
  <joint
    name="front_left_wheel_joint"
    type="continuous">
    <origin
      xyz="0 0 0"
      rpy="0 0 0" />
    <parent
      link="front_left_leg" />
    <child
      link="front_left_wheel" />
    <axis
      xyz="0.0536221602252057 0.998561297033278 0" />
  </joint>
  <link
    name="front_right_leg">
    <inertial>
      <origin
        xyz="7.17543933509424E-05 -2.10787107637889E-06 0.0331269063227782"
        rpy="0 0 0" />
      <mass
        value="0.114192911912365" />
      <inertia
        ixx="9.08560050080565E-05"
        ixy="-5.59525369207127E-07"
        ixz="2.58766391199689E-20"
        iyy="6.98180720072431E-05"
        iyz="1.24525199204899E-20"
        izz="3.65285981598051E-05" />
    </inertial>
    <visual>
      <origin
        xyz="0 0 0"
        rpy="0 0 0" />
      <geometry>
        <mesh
          filename="package://rk_bot/meshes/front_right_leg.STL" />
      </geometry>
      <material
        name="">
        <color
          rgba="0.792156862745098 0.819607843137255 0.933333333333333 1" />
      </material>
    </visual>
    <collision>
      <origin
        xyz="0 0 0"
        rpy="0 0 0" />
      <geometry>
        <mesh
          filename="package://rk_bot/meshes/front_right_leg.STL" />
      </geometry>
    </collision>
  </link>
  <joint
    name="front_right_leg_joint"
    type="revolute">
    <origin
      xyz="0.225002744800049 -0.0999998720644843 -0.0674600000000001"
      rpy="0 0 0" />
    <parent
      link="chassis" />
    <child
      link="front_right_leg" />
    <axis
      xyz="0 0 1" />
      <limit effort='1' velocity='10' lower='-0.5' upper='0.5'/>
  </joint>
  <transmission name="front_right_transmission">
    <type>transmission_interface/SimpleTransmission</type>
    <joint name="front_right_leg_joint">
      <hardwareInterface>EffortJointInterface</hardwareInterface>
    </joint>
    <actuator name="front_right_motor">
      <mechanicalReduction>50</mechanicalReduction>
      <hardwareInterface>hardware_interface/EffortJointInterface</hardwareInterface>
    </actuator>
  </transmission>
  <link
    name="front_right_wheel">
    <inertial>
      <origin
        xyz="-2.67179916532689E-06 2.61887457565779E-06 1.38777878078145E-17"
        rpy="0 0 0" />
      <mass
        value="0.0376991118430775" />
      <inertia
        ixx="1.08421533493758E-05"
        ixy="1.37665989689402E-07"
        ixz="-2.01832069462939E-21"
        iyy="1.60184638388169E-05"
        iyz="9.65733365155652E-23"
        izz="1.08384946548847E-05" />
    </inertial>
    <visual>
      <origin
        xyz="0 0 0"
        rpy="0 0 0" />
      <geometry>
        <mesh
          filename="package://rk_bot/meshes/front_right_wheel.STL" />
      </geometry>
      <material
        name="">
        <color
          rgba="0.792156862745098 0.819607843137255 0.933333333333333 1" />
      </material>
    </visual>
    <collision>
      <origin
        xyz="0 0 0"
        rpy="0 0 0" />
      <geometry>
        <mesh
          filename="package://rk_bot/meshes/front_right_wheel.STL" />
      </geometry>
    </collision>
  </link>
  <joint
    name="front_right_wheel_joint"
    type="continuous">
    <origin
      xyz="0 0 0"
      rpy="0 0 0" />
    <parent
      link="front_right_leg" />
    <child
      link="front_right_wheel" />
    <axis
      xyz="0.0265672232218073 0.999647029030889 0" />
  </joint>
  
  <link
    name="rear_axle">
    <inertial>
      <origin
        xyz="2.77555756156289E-17 -0.165 -4.35205466912218E-17"
        rpy="0 0 0" />
      <mass
        value="1.54193294429004" />
      <inertia
        ixx="0.00507108390089681"
        ixy="2.68227099963858E-21"
        ixz="9.68727758973099E-20"
        iyy="0.00577211997274141"
        iyz="-1.46819044190745E-20"
        izz="0.00507108390089681" />
    </inertial>
    <visual>
      <origin
        xyz="0 0 0"
        rpy="0 0 0" />
      <geometry>
        <mesh
          filename="package://rk_bot/meshes/rear_axle.STL" />
      </geometry>
      <material
        name="">
        <color
          rgba="0.752941176470588 0.752941176470588 0.752941176470588 1" />
      </material>
    </visual>
    <collision>
      <origin
        xyz="0 0 0"
        rpy="0 0 0" />
      <geometry>
        <mesh
          filename="package://rk_bot/meshes/rear_axle.STL" />
      </geometry>
    </collision>
  </link>
  <joint
    name="rear_axle_joint"
    type="continuous">
    <origin
      xyz="-0.224999999999999 0.165 0"
      rpy="0 0 0" />
    <parent
      link="chassis" />
    <child
      link="rear_axle" />
    <axis
      xyz="0 1 0" />
  </joint>
  <transmission name="rear_axle_transmission">
    <type>transmission_interface/SimpleTransmission</type>
    <joint name="rear_axle_joint">
      <hardwareInterface>VelocityJointInterface</hardwareInterface>
    </joint>
    <actuator name="rear_axle_motor">
      <mechanicalReduction>50</mechanicalReduction>
      <hardwareInterface>hardware_interface/VelocityJointInterface</hardwareInterface>
    </actuator>
  </transmission>
</robot>